{
  "nbformat": 4,
  "nbformat_minor": 0,
  "metadata": {
    "colab": {
      "provenance": []
    },
    "kernelspec": {
      "name": "python3",
      "display_name": "Python 3"
    },
    "language_info": {
      "name": "python"
    }
  },
  "cells": [
    {
      "cell_type": "code",
      "source": [
        "! pip install datawig"
      ],
      "metadata": {
        "colab": {
          "base_uri": "https://localhost:8080/"
        },
        "id": "-5KIyUr1e6A8",
        "outputId": "01419839-b92d-4a93-f0e5-15c696c7548e"
      },
      "execution_count": null,
      "outputs": [
        {
          "output_type": "stream",
          "name": "stdout",
          "text": [
            "Looking in indexes: https://pypi.org/simple, https://us-python.pkg.dev/colab-wheels/public/simple/\n",
            "Collecting datawig\n",
            "  Using cached datawig-0.2.0-py3-none-any.whl\n",
            "Collecting pandas==0.25.3\n",
            "  Using cached pandas-0.25.3.tar.gz (12.6 MB)\n",
            "  Preparing metadata (setup.py) ... \u001b[?25l\u001b[?25hdone\n",
            "Requirement already satisfied: typing==3.6.6 in /usr/local/lib/python3.9/dist-packages (from datawig) (3.6.6)\n",
            "Collecting mxnet==1.4.0\n",
            "  Using cached mxnet-1.4.0-py2.py3-none-manylinux1_x86_64.whl (29.6 MB)\n",
            "Collecting scikit-learn[alldeps]==0.22.1\n",
            "  Using cached scikit_learn-0.22.1-cp39-cp39-linux_x86_64.whl\n",
            "Collecting graphviz<0.9.0,>=0.8.1\n",
            "  Using cached graphviz-0.8.4-py2.py3-none-any.whl (16 kB)\n",
            "Requirement already satisfied: requests>=2.20.0 in /usr/local/lib/python3.9/dist-packages (from mxnet==1.4.0->datawig) (2.27.1)\n",
            "Collecting numpy<1.15.0,>=1.8.2\n",
            "  Using cached numpy-1.14.6.zip (4.9 MB)\n",
            "  Preparing metadata (setup.py) ... \u001b[?25l\u001b[?25hdone\n",
            "Requirement already satisfied: python-dateutil>=2.6.1 in /usr/local/lib/python3.9/dist-packages (from pandas==0.25.3->datawig) (2.8.2)\n",
            "Requirement already satisfied: pytz>=2017.2 in /usr/local/lib/python3.9/dist-packages (from pandas==0.25.3->datawig) (2022.7.1)\n",
            "Requirement already satisfied: joblib>=0.11 in /usr/local/lib/python3.9/dist-packages (from scikit-learn[alldeps]==0.22.1->datawig) (1.2.0)\n",
            "Requirement already satisfied: scipy>=0.17.0 in /usr/local/lib/python3.9/dist-packages (from scikit-learn[alldeps]==0.22.1->datawig) (1.10.1)\n",
            "Requirement already satisfied: six>=1.5 in /usr/local/lib/python3.9/dist-packages (from python-dateutil>=2.6.1->pandas==0.25.3->datawig) (1.16.0)\n",
            "Requirement already satisfied: charset-normalizer~=2.0.0 in /usr/local/lib/python3.9/dist-packages (from requests>=2.20.0->mxnet==1.4.0->datawig) (2.0.12)\n",
            "Requirement already satisfied: certifi>=2017.4.17 in /usr/local/lib/python3.9/dist-packages (from requests>=2.20.0->mxnet==1.4.0->datawig) (2022.12.7)\n",
            "Requirement already satisfied: urllib3<1.27,>=1.21.1 in /usr/local/lib/python3.9/dist-packages (from requests>=2.20.0->mxnet==1.4.0->datawig) (1.26.15)\n",
            "Requirement already satisfied: idna<4,>=2.5 in /usr/local/lib/python3.9/dist-packages (from requests>=2.20.0->mxnet==1.4.0->datawig) (3.4)\n",
            "Collecting scipy>=0.17.0\n",
            "  Using cached scipy-1.10.0-cp39-cp39-manylinux_2_17_x86_64.manylinux2014_x86_64.whl (34.4 MB)\n",
            "  Using cached scipy-1.9.3-cp39-cp39-manylinux_2_17_x86_64.manylinux2014_x86_64.whl (33.8 MB)\n",
            "  Using cached scipy-1.9.2-cp39-cp39-manylinux_2_17_x86_64.manylinux2014_x86_64.whl (33.8 MB)\n",
            "  Using cached scipy-1.9.1-cp39-cp39-manylinux_2_17_x86_64.manylinux2014_x86_64.whl (43.9 MB)\n",
            "  Using cached scipy-1.9.0-cp39-cp39-manylinux_2_17_x86_64.manylinux2014_x86_64.whl (43.9 MB)\n",
            "  Using cached scipy-1.8.1-cp39-cp39-manylinux_2_17_x86_64.manylinux2014_x86_64.whl (42.2 MB)\n",
            "  Using cached scipy-1.8.0-cp39-cp39-manylinux_2_17_x86_64.manylinux2014_x86_64.whl (42.1 MB)\n",
            "  Using cached scipy-1.7.3-cp39-cp39-manylinux_2_17_x86_64.manylinux2014_x86_64.whl (39.8 MB)\n",
            "  Using cached scipy-1.7.2-cp39-cp39-manylinux_2_17_x86_64.manylinux2014_x86_64.whl (39.8 MB)\n",
            "  Using cached scipy-1.7.1-cp39-cp39-manylinux_2_5_x86_64.manylinux1_x86_64.whl (28.5 MB)\n",
            "  Using cached scipy-1.7.0-cp39-cp39-manylinux_2_5_x86_64.manylinux1_x86_64.whl (28.4 MB)\n",
            "  Using cached scipy-1.6.3-cp39-cp39-manylinux1_x86_64.whl (27.3 MB)\n",
            "  Using cached scipy-1.6.2-cp39-cp39-manylinux1_x86_64.whl (27.3 MB)\n",
            "  Using cached scipy-1.6.1-cp39-cp39-manylinux1_x86_64.whl (27.3 MB)\n",
            "  Using cached scipy-1.6.0-cp39-cp39-manylinux1_x86_64.whl (27.3 MB)\n",
            "  Using cached scipy-1.5.4-cp39-cp39-manylinux1_x86_64.whl (25.8 MB)\n",
            "Building wheels for collected packages: pandas, numpy\n",
            "  \u001b[1;31merror\u001b[0m: \u001b[1msubprocess-exited-with-error\u001b[0m\n",
            "  \n",
            "  \u001b[31m×\u001b[0m \u001b[32mpython setup.py bdist_wheel\u001b[0m did not run successfully.\n",
            "  \u001b[31m│\u001b[0m exit code: \u001b[1;36m1\u001b[0m\n",
            "  \u001b[31m╰─>\u001b[0m See above for output.\n",
            "  \n",
            "  \u001b[1;35mnote\u001b[0m: This error originates from a subprocess, and is likely not a problem with pip.\n",
            "  Building wheel for pandas (setup.py) ... \u001b[?25lerror\n",
            "\u001b[31m  ERROR: Failed building wheel for pandas\u001b[0m\u001b[31m\n",
            "\u001b[0m\u001b[?25h  Running setup.py clean for pandas\n",
            "  \u001b[1;31merror\u001b[0m: \u001b[1msubprocess-exited-with-error\u001b[0m\n",
            "  \n",
            "  \u001b[31m×\u001b[0m \u001b[32mpython setup.py bdist_wheel\u001b[0m did not run successfully.\n",
            "  \u001b[31m│\u001b[0m exit code: \u001b[1;36m1\u001b[0m\n",
            "  \u001b[31m╰─>\u001b[0m See above for output.\n",
            "  \n",
            "  \u001b[1;35mnote\u001b[0m: This error originates from a subprocess, and is likely not a problem with pip.\n",
            "  Building wheel for numpy (setup.py) ... \u001b[?25lerror\n",
            "\u001b[31m  ERROR: Failed building wheel for numpy\u001b[0m\u001b[31m\n",
            "\u001b[0m\u001b[?25h  Running setup.py clean for numpy\n",
            "  \u001b[1;31merror\u001b[0m: \u001b[1msubprocess-exited-with-error\u001b[0m\n",
            "  \n",
            "  \u001b[31m×\u001b[0m \u001b[32mpython setup.py clean\u001b[0m did not run successfully.\n",
            "  \u001b[31m│\u001b[0m exit code: \u001b[1;36m1\u001b[0m\n",
            "  \u001b[31m╰─>\u001b[0m See above for output.\n",
            "  \n",
            "  \u001b[1;35mnote\u001b[0m: This error originates from a subprocess, and is likely not a problem with pip.\n",
            "\u001b[31m  ERROR: Failed cleaning build dir for numpy\u001b[0m\u001b[31m\n",
            "\u001b[0mFailed to build pandas numpy\n",
            "Installing collected packages: numpy, graphviz, scipy, pandas, mxnet, scikit-learn, datawig\n",
            "  Attempting uninstall: numpy\n",
            "    Found existing installation: numpy 1.22.4\n",
            "    Uninstalling numpy-1.22.4:\n",
            "      Successfully uninstalled numpy-1.22.4\n",
            "  \u001b[1;31merror\u001b[0m: \u001b[1msubprocess-exited-with-error\u001b[0m\n",
            "  \n",
            "  \u001b[31m×\u001b[0m \u001b[32mRunning setup.py install for numpy\u001b[0m did not run successfully.\n",
            "  \u001b[31m│\u001b[0m exit code: \u001b[1;36m1\u001b[0m\n",
            "  \u001b[31m╰─>\u001b[0m See above for output.\n",
            "  \n",
            "  \u001b[1;35mnote\u001b[0m: This error originates from a subprocess, and is likely not a problem with pip.\n",
            "  Running setup.py install for numpy ... \u001b[?25l\u001b[?25herror\n",
            "  Rolling back uninstall of numpy\n",
            "  Moving to /usr/local/bin/f2py\n",
            "   from /tmp/pip-uninstall-fe224kjb/f2py\n",
            "  Moving to /usr/local/bin/f2py3\n",
            "   from /tmp/pip-uninstall-fe224kjb/f2py3\n",
            "  Moving to /usr/local/bin/f2py3.9\n",
            "   from /tmp/pip-uninstall-fe224kjb/f2py3.9\n",
            "  Moving to /usr/local/lib/python3.9/dist-packages/numpy-1.22.4.dist-info/\n",
            "   from /usr/local/lib/python3.9/dist-packages/~umpy-1.22.4.dist-info\n",
            "  Moving to /usr/local/lib/python3.9/dist-packages/numpy.libs/\n",
            "   from /usr/local/lib/python3.9/dist-packages/~umpy.libs\n",
            "  Moving to /usr/local/lib/python3.9/dist-packages/numpy/\n",
            "   from /usr/local/lib/python3.9/dist-packages/~umpy\n",
            "\u001b[1;31merror\u001b[0m: \u001b[1mlegacy-install-failure\u001b[0m\n",
            "\n",
            "\u001b[31m×\u001b[0m Encountered error while trying to install package.\n",
            "\u001b[31m╰─>\u001b[0m numpy\n",
            "\n",
            "\u001b[1;35mnote\u001b[0m: This is an issue with the package mentioned above, not pip.\n",
            "\u001b[1;36mhint\u001b[0m: See above for output from the failure.\n"
          ]
        }
      ]
    },
    {
      "cell_type": "code",
      "source": [
        "# Read input data\n",
        "df = pd.read_csv('../data/Heart.csv')\n",
        "df.head()"
      ],
      "metadata": {
        "id": "7L16xcSYeABh"
      },
      "execution_count": null,
      "outputs": []
    }
  ]
}